<?xml version="1.0" ?>
<!-- =================================================================================== -->
<!-- |    This document was autogenerated by xacro from /home/florent/devel/isae/install/share/ur_description/urdf/ur5_joint_limited_robot.urdf.xacro | -->
<!-- |    EDITING THIS FILE BY HAND IS NOT RECOMMENDED                                 | -->
<!-- =================================================================================== -->
<robot name="ur5" xmlns:xacro="http://www.ros.org/wiki/xacro">

  <!-- Some definition -->
  
  <material name="blue">
    <color rgba="0 0 0.8 1"/>
  </material>

  <material name="white">
    <color rgba="1 1 1 1"/>
  </material>
  
  <material name="lightgrey">
    <color rgba="0.7 0.7 0.7 1.0"/>
  </material>
  
  
  <!-- BGN - Robot description -->

  <link name="world"/>
  
  <joint name="world_joint" type="fixed">
    <parent link="world"/>
    <child link="base_link"/>
    <origin rpy="0.0 0.0 0.0" xyz="0.0 0.0 4.0"/>
  </joint>
  
  <link name="base_link">
    <visual>
      <geometry>
        <box size="1.0 1.0 0.05"/>
      </geometry>
      <origin rpy="0 0 0" xyz="0 0 0"/>
      <material name="blue"/>
    </visual>
    <collision>
      <geometry>
        <box size="1.0 1.0 0.05"/>
      </geometry>
      <origin rpy="0 0 0" xyz="0 0 0"/>
    </collision>
    <inertial>
      <mass value="1.0"/>
      <origin rpy="0 0 0" xyz="0 0 0"/>
      <inertia ixx="0.08" ixy="0.0" ixz="0.0" iyy="0.08" iyz="0.0" izz="0.16"/>
    </inertial>
  </link>


  <joint name="base_link__link_01" type="revolute">
    <parent link="base_link"/>
    <child link="link_01"/>
    <origin rpy="3.14 0.0 0.0" xyz="0 0 0"/>
    <axis xyz="0 0 1"/>
    <limit effort="150.0" lower="-3.14159265" upper="3.14159265" velocity="3.15"/>
    <dynamics damping="0.0" friction="0.0"/>
  </joint>
  <transmission name="base_link__link_01_trans">
    <type>transmission_interface/SimpleTransmission</type>
    <joint name="base_link__link_01">
      <hardwareInterface>PositionJointInterface</hardwareInterface>
    </joint>
    <actuator name="base_link__link_01_motor">
      <mechanicalReduction>1</mechanicalReduction>
    </actuator>
  </transmission>
  
  
  <link name="link_01">
    <visual>
      <geometry>
        <cylinder length="0.1" radius="0.4"/>
      </geometry>
      <origin rpy="0 0 0" xyz="0 0 0"/>
      <material name="white"/>
    </visual>
    <collision>
      <geometry>
        <cylinder length="0.1" radius="0.4"/>
      </geometry>
      <origin rpy="0 0 0" xyz="0 0 0"/>
    </collision>
    <inertial>
      <mass value="4.0"/>
      <origin rpy="0 0 0" xyz="0.0 0.0 0.0"/>
      <inertia ixx="0.00125" ixy="0.0" ixz="0.0" iyy="0.00125" iyz="0.0" izz="0.08"/>
    </inertial>
  </link>


  <joint name="link_01__link_02" type="revolute">
    <parent link="link_01"/>
    <child link="link_02"/>
    <origin rpy="1.57 0 0 " xyz="0 0 0"/>
    <axis xyz="0 0 1"/>
    <limit effort="150.0" lower="-3.14159265" upper="3.14159265" velocity="3.15"/>
    <dynamics damping="0.0" friction="0.0"/>
  </joint>
  <transmission name="link_01__link_02_trans">
    <type>transmission_interface/SimpleTransmission</type>
    <joint name="link_01__link_02">
      <hardwareInterface>PositionJointInterface</hardwareInterface>
    </joint>
    <actuator name="link_01__link_02_motor">
      <mechanicalReduction>1</mechanicalReduction>
    </actuator>
  </transmission>
  

  <link name="link_02">
    <visual>
      <geometry>
        <cylinder length="3" radius="0.05"/>
      </geometry>
      <origin rpy="0 1.57 0" xyz="1.5 0 0"/>
      <material name="blue"/>
    </visual>
    <collision>
      <geometry>
        <cylinder length="3" radius="0.05"/>
      </geometry>
      <origin rpy="0 1.57 0" xyz="1.5 0 0"/>
    </collision>
    <inertial>
      <mass value="4.0"/>
      <origin rpy="0 1.57 0" xyz="0.0 0.0 0.0"/>
      <inertia ixx="4.5" ixy="0.0" ixz="0.0" iyy="4.5" iyz="0.0" izz="0.00125"/>
    </inertial>
  </link>


  <joint name="link_02__link_03" type="prismatic">
    <parent link="link_02"/>
    <child link="link_03"/>
    <origin xyz="1 0 0"/>
    <axis xyz="1 0 0"/>
    <limit effort="150.0" lower="0" upper="2" velocity="3.15"/>
    <dynamics damping="100" friction="100"/>
  </joint>
  <transmission name="link_02__link_03_trans">
    <type>transmission_interface/SimpleTransmission</type>
    <joint name="link_02__link_03">
      <hardwareInterface>PositionJointInterface</hardwareInterface>
    </joint>
    <actuator name="link_02__link_03_motor">
      <mechanicalReduction>1</mechanicalReduction>
    </actuator>
  </transmission>
  
  
  <link name="link_03">
    <visual>
      <geometry>
        <cylinder length="2.0" radius="0.05"/>
      </geometry>
      <origin rpy="0 1.57 0" xyz="1 0 0"/>
      <material name="white"/>
    </visual>
    <collision>
      <geometry>
        <cylinder length="2" radius="0.05"/>
      </geometry>
      <origin rpy="0 1.57 0" xyz="1 0 0"/>
    </collision>
    <inertial>
      <mass value="4.0"/>
      <origin rpy="0 1.57 0" xyz="0.0 0.0 0.0"/>
      <inertia ixx="2" ixy="0.0" ixz="0.0" iyy="2" iyz="0.0" izz="0.00125"/>
    </inertial>
  </link>


  <joint name="link_03__link_04" type="revolute">
    <parent link="link_03"/>
    <child link="link_04"/>
    <origin xyz="2 0 0"/>
    <axis xyz="0 0 1"/>
    <limit effort="150.0" lower="-3.14159265" upper="3.14159265" velocity="3.15"/>
    <dynamics damping="100" friction="100"/>
  </joint>
  <transmission name="link_02__link_03_trans">
    <type>transmission_interface/SimpleTransmission</type>
    <joint name="link_02__link_03">
      <hardwareInterface>PositionJointInterface</hardwareInterface>
    </joint>
    <actuator name="link_02__link_03_motor">
      <mechanicalReduction>1</mechanicalReduction>
    </actuator>
  </transmission>
  

  <link name="link_04">
    <visual>
      <geometry>
        <cylinder length="1" radius="0.02"/>
      </geometry>
      <origin rpy="0 1.57 0" xyz="0.5 0 0"/>
      <material name="blue"/>
    </visual>
    <collision>
      <geometry>
        <cylinder length="1" radius="0.02"/>
      </geometry>
      <origin rpy="0 1.57 0" xyz="0.5 0 0"/>
    </collision>
    <inertial>
      <mass value="4.0"/>
      <origin rpy="0 1.57 0" xyz="0.0 0.0 0.0"/>
      <inertia ixx="0.5" ixy="0.0" ixz="0.0" iyy="0.5" iyz="0.0" izz="0.0002"/>
    </inertial>
  </link>


  <joint name="link_04__link_05" type="revolute">
    <parent link="link_04"/>
    <child link="link_05"/>
    <origin xyz="1 0 0"/>
    <axis xyz="0 0 1"/>
    <limit effort="28.0" lower="-3.14159265" upper="3.14159265" velocity="3.2"/>
    <dynamics damping="0.0" friction="0.0"/>
  </joint>
  <transmission name="link_03__link_04_trans">
    <type>transmission_interface/SimpleTransmission</type>
    <joint name="link_03__link_04">
      <hardwareInterface>PositionJointInterface</hardwareInterface>
    </joint>
    <actuator name="link_03__link_04_motor">
      <mechanicalReduction>1</mechanicalReduction>
    </actuator>
  </transmission>
  

  <link name="link_05">
    <visual>
      <geometry>
        <cylinder length="0.2" radius="0.03"/>
      </geometry>
      <origin rpy="0 1.57 0" xyz="0.1 0 0"/>
      <material name="white"/>
    </visual>
    <collision>
      <geometry>
        <cylinder length="0.2" radius="0.03"/>
      </geometry>
      <origin rpy="0 1.57 0" xyz="0.1 0 0"/>
    </collision>
    <inertial>
      <mass value="4.0"/>
      <origin rpy="0 1.57 0" xyz="0.0 0.0 0.0"/>
      <inertia ixx="0.02" ixy="0.0" ixz="0.0" iyy="0.02" iyz="0.0" izz="0.0004"/>
    </inertial>
  </link>
  
  
  <joint name="ee_fixed_joint" type="fixed">
    <parent link="link_05"/>
    <child link="ee_link"/>
    <origin rpy="0.0 1.57 0.0" xyz="0.2 0.0 0.0"/>
  </joint>
  

  <link name="ee_link">
    <visual>
        <geometry>
            <cylinder radius="0.001" length="0.001"/>
        </geometry>
        <origin rpy="0 0 0" xyz="0 0 0"/>
        <material name="white"/>
    </visual>
    <collision>
      <geometry>
        <cylinder radius="0.001" length="0.001"/>
      </geometry>
      <origin rpy="0 0 0" xyz="0 0 0"/>
    </collision>
  </link>
  
  <!-- END - Robot description -->

  <!-- Gazebo-->
  
  <gazebo>
    <plugin filename="libgazebo_ros_control.so" name="ros_control">
      <!--robotNamespace>/</robotNamespace-->
      <!--robotSimType>gazebo_ros_control/DefaultRobotHWSim</robotSimType-->
    </plugin>

  </gazebo>
  
</robot>
